Workbook

Sheet 1. Cadastro de Insumos
A1: Ingrediente | B1: Marca/Tipo | C1: Unidade (kg, ml, un) | D1: Qtd na Embalagem | E1: Preço de Compra (R$) | F1: Custo Unitário (R$)
A2: TRIGO | B2: ANIELLA | C2: kg | D2: 5000 | E2: 14 | F2: =IF(AND(D2>0, E2>0), E2/D2, 0) -> 0.0028
A3: AÇÚCAR | B3: PORTO BELLO | C3: kg | D3: 5000 | E3: 20 | F3: =IF(AND(D3>0, E3>0), E3/D3, 0) -> 0.004
A4: OVO | B4: Q/UM | C4: dz | D4: 30 | E4: 20 | F4: =IF(AND(D4>0, E4>0), E4/D4, 0) -> 0.66666667
A5: FERMENTO | B5: ROYAL | C5: PT | D5: 250 | E5: 11 | F5: =IF(AND(D5>0, E5>0), E5/D5, 0) -> 0.044
A6: EMUSTAB | B6: 4 RODAS | C6: KG | D6: 1000 | E6: 45 | F6: =IF(AND(D6>0, E6>0), E6/D6, 0) -> 0.045
F7: =IF(AND(D7>0, E7>0), E7/D7, 0) -> 0
A8: RECHEIOS
A9: LEITE CONDENSADO | B9: tirol | C9: cx | D9: 395 | E9: 6 | F9: =IF(AND(D9>0, E9>0), E9/D9, 0) -> 0.015189873
A10: CREME DE LEITE | B10: tirol | C10: cx | D10: 200 | E10: 3 | F10: =IF(AND(D10>0, E10>0), E10/D10, 0) -> 0.015
A11: CHOCOLATE EM PÓ | B11: MELKEN | C11: KG | D11: 1000 | E11: 80 | F11: =IF(AND(D11>0, E11>0), E11/D11, 0) -> 0.08
A12: COCO | B12: DO VALLE | C12: KG | D12: 1000 | E12: 55 | F12: =IF(AND(D12>0, E12>0), E12/D12, 0) -> 0.055
A13: AMENDOIM | B13: VARIADO | C13: KG | D13: 1000 | E13: 30 | F13: =IF(AND(D13>0, E13>0), E13/D13, 0) -> 0.03
A14: LEITE EM PÓ | B14: NINHO | C14: GR | D14: 400 | E14: 20 | F14: =IF(AND(D14>0, E14>0), E14/D14, 0) -> 0.05
A15: MORANGO | B15: CX | C15: CX | D15: 250 | E15: 15 | F15: =IF(AND(D15>0, E15>0), E15/D15, 0) -> 0.06
A16: BOMBOM OURO BRANCO | B16: LACTA | C16: PT | D16: 50 | E16: 70 | F16: =IF(AND(D16>0, E16>0), E16/D16, 0) -> 1.4
A17: BOMBOM SONHO DE VALSA | B17: LACTA | C17: PT | D17: 50 | E17: 70 | F17: =IF(AND(D17>0, E17>0), E17/D17, 0) -> 1.4
F18: =IF(AND(D18>0, E18>0), E18/D18, 0) -> 0

Sheet 2. Ficha Técnica
B2: RECEITA: | C2: BOLO DE BRIGADEIRO BRANCO 1 KG | G2: PREÇO FINAL DE VENDA SUGERIDO
B4: Ingrediente | C4: Qtd na Receita | D4: Custo Unitário (R$) | E4: Subtotal Item (R$) | G4: Item de Custo | H4: Valor/Taxa | I4: Subtotal (R$)
B5: trigo | C5: 175 | D5: ='1. Cadastro de Insumos'!E2/'1. Cadastro de Insumos'!D2 -> 0.0028 | E5: =C5*D5 -> 0.49 | G5: Custo de Insumos (Automático) | I5: =E16 -> 16.428333
B6: açúcar | C6: 150 | D6: ='1. Cadastro de Insumos'!E3/'1. Cadastro de Insumos'!D3 -> 0.004 | E6: =C6*D6 -> 0.6 | G6: Custos Fixos/Utilidades (Gás/Luz) - % | H6: 0.1 | I6: =I5*H6 -> 1.6428333
B7: ovo | C7: 3.5 | D7: ='1. Cadastro de Insumos'!E4/'1. Cadastro de Insumos'!D4 -> 0.66666667 | E7: =C7*D7 -> 2.3333333 | G7: Mão de Obra (Pro-labore) - % | H7: 0.2 | I7: =(I5+I6)*H7 -> 3.6142333
B8: fermento | C8: 7.5 | D8: ='1. Cadastro de Insumos'!E5/'1. Cadastro de Insumos'!D5 -> 0.044 | E8: =C8*D8 -> 0.33 | G8: SUBTOTAL (CUSTO DE PRODUÇÃO) | I8: =SUM(I5:I7) -> 21.6854
B9: emustab | C9: 15 | D9: ='1. Cadastro de Insumos'!E6/'1. Cadastro de Insumos'!D6 -> 0.045 | E9: =C9*D9 -> 0.675 | G9: Margem de Lucro Desejada - % | H9: 1.5
E10: =SUM(E5:E9) -> 4.4283333 | G10: TOTAL | I10: =I8*(1+H9) -> 54.2135
B11: RECHEIO
B12: leite condensado | C12: 1 | D12: ='1. Cadastro de Insumos'!E9*C12 -> 6 | E12: =C12*D12 -> 6 | G12: Embalagem e Descartáveis | H12: 1 | I12: 2.5
B13: creme de leite | C13: 2 | D13: ='1. Cadastro de Insumos'!E10 -> 3 | E13: =C13*D13 -> 6
E14: =C14*D14 -> 0 | G14: PREÇO FINAL DE VENDA SUGERIDO | I14: =SUM(I10:I13) -> 56.7135
E15: =SUM(E12:E14) -> 12
C16: CUSTO TOTAL DE INSUMOS: | E16: =SUM(E10,E15) -> 16.428333
B21: RECEITA: | C21: BOLO DE BRIGADEIRO DE CHOCOLATE 1 KG | G21: PREÇO FINAL DE VENDA SUGERIDO
B23: Ingrediente | C23: Qtd na Receita | D23: Custo Unitário (R$) | E23: Subtotal Item (R$) | G23: Item de Custo | H23: Valor/Taxa | I23: Subtotal (R$)
B24: trigo | C24: 175 | D24: ='1. Cadastro de Insumos'!F2 -> 0.0028 | E24: =C24*D24 -> 0.49 | G24: Custo de Insumos (Automático) | I24: =SUM(E29:E33) -> 16.428333
B25: açúcar | C25: 150 | D25: ='1. Cadastro de Insumos'!F3 -> 0.004 | E25: =C25*D25 -> 0.6 | G25: Custos Fixos/Utilidades (Gás/Luz) - % | H25: 0.1 | I25: =I24*H25 -> 1.6428333
B26: ovo | C26: 3.5 | D26: ='1. Cadastro de Insumos'!F4 -> 0.66666667 | E26: =C26*D26 -> 2.3333333 | G26: Mão de Obra (Pro-labore) - % | H26: 0.2 | I26: =(I24+I25)*H26 -> 3.6142333
B27: fermento | C27: 7.5 | D27: ='1. Cadastro de Insumos'!F5 -> 0.044 | E27: =C27*D27 -> 0.33 | G27: SUBTOTAL (CUSTO DE PRODUÇÃO) | I27: =SUM(I24:I26) -> 21.6854
B28: emustab | C28: 15 | D28: ='1. Cadastro de Insumos'!F6 -> 0.045 | E28: =C28*D28 -> 0.675 | G28: Margem de Lucro Desejada - % | H28: 1.5
E29: =SUM(E24:E28) -> 4.4283333 | G29: TOTAL | I29: =I27*(1+H28) -> 54.2135
B31: RECHEIO | G31: CHOCOLATE EM PÓ | I31: =E34 -> 4.8
B32: leite condensado | C32: 1 | D32: ='1. Cadastro de Insumos'!E9 -> 6 | E32: =C32*D32 -> 6 | G32: Embalagem e Descartáveis | H32: 1 | I32: 2.5
B33: creme de leite | C33: 2 | D33: ='1. Cadastro de Insumos'!E10 -> 3 | E33: =C33*D33 -> 6
B34: CHOCOLATE EM PÓ | C34: 60 | D34: ='1. Cadastro de Insumos'!F11 -> 0.08 | E34: =C34*D34 -> 4.8 | G34: PREÇO FINAL DE VENDA SUGERIDO | I34: =SUM(I29:I33) -> 61.5135
E35: =SUM(E32:E34) -> 16.8
C36: CUSTO TOTAL DE INSUMOS: | E36: =SUM(E29,E35) -> 21.228333
B41: RECEITA: | C41: BOLO DE BEJINHO 1 KG | G41: PREÇO FINAL DE VENDA SUGERIDO
B43: Ingrediente | C43: Qtd na Receita | D43: Custo Unitário (R$) | E43: Subtotal Item (R$) | G43: Item de Custo | H43: Valor/Taxa | I43: Subtotal (R$)
B44: trigo | C44: 175 | D44: ='1. Cadastro de Insumos'!F2 -> 0.0028 | E44: =C44*D44 -> 0.49 | G44: Custo de Insumos (Automático) | I44: =SUM(E49:E53) -> 16.428333
B45: açúcar | C45: 150 | D45: ='1. Cadastro de Insumos'!F3 -> 0.004 | E45: =C45*D45 -> 0.6 | G45: Custos Fixos/Utilidades (Gás/Luz) - % | H45: 0.1 | I45: =I44*H45 -> 1.6428333
B46: ovo | C46: 3.5 | D46: ='1. Cadastro de Insumos'!F4 -> 0.66666667 | E46: =C46*D46 -> 2.3333333 | G46: Mão de Obra (Pro-labore) - % | H46: 0.2 | I46: =(I44+I45)*H46 -> 3.6142333
B47: fermento | C47: 7.5 | D47: ='1. Cadastro de Insumos'!F5 -> 0.044 | E47: =C47*D47 -> 0.33 | G47: SUBTOTAL (CUSTO DE PRODUÇÃO) | I47: =SUM(I44:I46) -> 21.6854
B48: emustab | C48: 15 | D48: ='1. Cadastro de Insumos'!F6 -> 0.045 | E48: =C48*D48 -> 0.675 | G48: Margem de Lucro Desejada - % | H48: 1.5
E49: =SUM(E44:E48) -> 4.4283333 | G49: TOTAL | I49: =I47*(1+H48) -> 54.2135
B51: RECHEIO | G51: COCO | I51: =E54 -> 5.5
B52: leite condensado | C52: 1 | D52: ='1. Cadastro de Insumos'!E9 -> 6 | E52: =C52*D52 -> 6 | G52: Embalagem e Descartáveis | H52: 1 | I52: 2.5
B53: creme de leite | C53: 2 | D53: ='1. Cadastro de Insumos'!E10 -> 3 | E53: =C53*D53 -> 6
B54: COCO | C54: 100 | D54: ='1. Cadastro de Insumos'!F12 -> 0.055 | E54: =C54*D54 -> 5.5 | G54: PREÇO FINAL DE VENDA SUGERIDO | I54: =SUM(I49:I53) -> 62.2135
...
